Workbook
Name LongevityShock: Assumptions!$D$1
Name MaxAge: Assumptions!$B$1
Name RateShift: Assumptions!$E$1
Name RetirementAge: Assumptions!$A$1
Name ValuationYear: Assumptions!$C$1

Sheet Read me
B1: Longevity risk in a Dutch pension portfolio: Excel model
B2: Author: Daniel Wolff · Valuation date 30-09-2026
B4: Purpose
B5: This workbook independently rebuilds the liability valuation of the Python model for 10 sample participants, reconciles the results with Python, shows how the best-estimate liability (BEL) reacts to longevity and interest rate shocks, and summarises the fund-level results on the Dashboard.
B7: How the project fits together
B8: Step | C8: What it does
B9: 1. R | C9: Lee-Carter mortality model fitted on Dutch HMD data (1990-2023), projected 50 years ahead with 1,000 simulated scenarios.
B10: 2. Python | C10: Synthetic fund of 100,000 participants: survival along the generational diagonal, expected cash flows, discounting with the EIOPA curve, BEL, stochastic BEL and stress tests. Exports 10 participants to this workbook.
B11: 3. Excel | C11: This workbook: rebuilds the calculation for the 10 participants, checks it against Python and adds sensitivities and a dashboard.
B13: Sheets
B14: Sheet | C14: Contents
B15: Read me | C15: This page.
B16: Dashboard | C16: Summary of all results. Every number is a link to another sheet.
B17: Participants | C17: The 10 exported participants (id, sex, age, accrued pension) and Python's BEL per participant.
B18: q_paths | C18: One-year death probabilities along each participant's generational diagonal, t = 0..80 years from the valuation date.
B19: Discount | C19: Discount factors from the EIOPA risk-free curve (spot, no volatility adjustment), t = 0..80.
B20: CF_python | C20: Python's expected cash flows per participant, used only for the reconciliation.
B21: Assumptions | C21: Model inputs (named ranges) and the two-way sensitivity tables per participant.
B22: Calc | C22: The valuation for the selected participant: age, q, survival, payment indicator, cash flow, discount factor, present value, BEL and duration.
B23: Reconciliation | C23: Data Table that runs Calc for all 10 participants and compares BEL Excel with BEL Python.
B24: Python_results | C24: Fund-level results from Python (BEL, duration, stress tests, stochastic BEL). Blue values are copied from Python.
B26: Inputs
B27: Input | C27: Meaning
B28: RetirementAge | C28: Age at which pension payments start (Assumptions!A1).
B29: MaxAge | C29: Age at which the mortality table is closed with q = 1 (Assumptions!B1).
B30: ValuationYear | C30: Year of the valuation date (Assumptions!C1).
B31: LongevityShock | C31: Relative decrease of all mortality rates, e.g. 20% (Assumptions!D1). Keep at 0 for the reconciliation.
B32: RateShift | C32: Parallel shift of the spot rates, e.g. +1% (Assumptions!E1). Keep at 0 for the reconciliation.
B33: Selected id | C33: Participant shown on Calc and the Dashboard (Reconciliation!B1).
B35: Calculation (sheet Calc, one row per year t)
B36: Item | C36: Formula
B37: Survival | C37: S(0) = 1 and S(t) = S(t-1) × (1 − q(t-1))
B38: Cash flow | C38: CF(t) = pension × S(t) × 1[age + t ≥ RetirementAge], paid at the start of each year
B39: Discount factor | C39: DF(t) = (1 + r(t) + RateShift)^(−t), with r(t) recovered from the exported DF
B40: BEL | C40: Sum of CF(t) × DF(t)
B41: Duration | C41: Sum of t × CF(t) × DF(t), divided by BEL
B43: How to use
B44: 1. Change the participant id in Reconciliation!B1 to see that participant on Calc and the Dashboard.
B45: 2. Change LongevityShock or RateShift on Assumptions to see the effect. The reconciliation will then show CHECK, because Python was run without shocks.
B46: 3. If the Data Tables do not update, press F9 or set Formulas → Calculation Options → Automatic.
...

Sheet Dashboard
B1: Longevity risk in a Dutch pension portfolio
B2: Valuation date 30-09-2026 · Lee-Carter mortality projection (HMD, NL 1990-2023) · EIOPA risk-free curve, no VA
B4: Fund BEL (€ bn) | D4: Duration (years) | F4: Longevity capital, own model | H4: Longevity capital, std formula | J4: Excel vs Python
B5: =Python_results!B5 -> 12.278379 | D5: =Python_results!C5 -> 14.489911 | F5: =Python_results!B20 -> 0.047481838 | H5: =Python_results!B21 -> 0.078075451 | J5: =Reconciliation!F17 -> All reconciled
B6: Best estimate, central projection | D6: Weighted average payment time | F6: ="€"&TEXT(Python_results!B18,"#,##0")&" mln at 99.5%" -> €583,0 mln at 99.5% | H6: ="€"&TEXT(Python_results!D6,"#,##0")&" mln (−20% q)" -> €958,640 mln (−20% q) | J6: 10 sample participants
B8: Fund-level stress tests (Python model, 100,000 participants)
B9: Scenario | C9: BEL (€ bn) | D9: Duration (yrs) | E9: Change (€ mln) | F9: Change (%)
B10: =Python_results!A5 -> Base | C10: =Python_results!B5 -> 12.278379 | D10: =Python_results!C5 -> 14.489911 | E10: =Python_results!D5 -> 0 | F10: =Python_results!E5 -> 0
B11: =Python_results!A6 -> Longevity -20% q | C11: =Python_results!B6 -> 13.237019 | D11: =Python_results!C6 -> 14.911614 | E11: =Python_results!D6 -> 958.63997 | F11: =Python_results!E6 -> 0.078075451
B12: =Python_results!A7 -> Rates -1% | C12: =Python_results!B7 -> 14.231167 | D12: =Python_results!C7 -> 15.950989 | E12: =Python_results!D7 -> 1952.7884 | F12: =Python_results!E7 -> 0.15904285
B13: =Python_results!A8 -> Rates +1% | C13: =Python_results!B8 -> 10.750233 | D13: =Python_results!C8 -> 13.190896 | E13: =Python_results!D8 -> -1528.1457 | F13: =Python_results!E8 -> -0.12445826
B14: Longevity −20% q is the Solvency II standard-formula shock; rates ±1% is a parallel sensitivity, not the maturity-dependent SF shock.
B17: Excel reconciliation (10 sample participants)
B18: Total BEL Excel (€) | C18: =Reconciliation!B17 -> 1232776.7
B19: Total BEL Python (€) | C19: =Reconciliation!D17 -> 1232776.7
B20: Difference (€) | C20: =Reconciliation!E17 -> 0
B21: Status | C21: =Reconciliation!F17 -> All reconciled
B24: Selected participant (change the id in Reconciliation!B1)
B25: Participant id | C25: =Reconciliation!B1 -> 77945
B26: Sex | C26: =Calc!B2 -> Male
B27: Age at valuation | C27: =Calc!B3 -> 82
B28: Accrued pension (€ / yr) | C28: =Calc!B4 -> 21911.59
B29: BEL Excel (€) | C29: =Calc!L6 -> 146954.86
B30: BEL Python (€) | C30: =Calc!B5 -> 146954.86
B31: Duration (years) | C31: =Calc!L7 -> 4.2558192
B40: Participant sensitivities: % change in BEL
B41: Retiree (id 77945): mainly longevity-sensitive | G41: Active (id 7142, age 52): mainly rate-sensitive
B42: Longevity ↓ / Rate → | C42: =Assumptions!H26 -> -0.01 | D42: =Assumptions!I26 -> 0 | E42: =Assumptions!J26 -> 0.01 | G42: Longevity ↓ / Rate → | H42: =Assumptions!N26 -> -0.01 | I42: =Assumptions!O26 -> 0 | J42: =Assumptions!P26 -> 0.01
B43: =Assumptions!G27 -> 0 | C43: =Assumptions!H27 -> 0.042869552 | D43: =Assumptions!I27 -> 0 | E43: =Assumptions!J27 -> -0.039473756 | G43: =Assumptions!M27 -> 0 | H43: =Assumptions!N27 -> 0.2839144 | I43: =Assumptions!O27 -> 0 | J43: =Assumptions!P27 -> -0.21542491
B44: =Assumptions!G28 -> 0.1 | C44: =Assumptions!H28 -> 0.10225907 | D44: =Assumptions!I28 -> 0.054277395 | E44: =Assumptions!J28 -> 0.010266768 | G44: =Assumptions!M28 -> 0.1 | H44: =Assumptions!N28 -> 0.32887808 | I44: =Assumptions!O28 -> 0.032364584 | J44: =Assumptions!P28 -> -0.19189048
B45: =Assumptions!G29 -> 0.2 | C45: =Assumptions!H29 -> 0.1708609 | D45: =Assumptions!I29 -> 0.11662644 | E45: =Assumptions!J29 -> 0.067102274 | G45: =Assumptions!M29 -> 0.2 | H45: =Assumptions!N29 -> 0.37845158 | I45: =Assumptions!O29 -> 0.067783202 | J45: =Assumptions!P29 -> -0.16631551
B47: Key message: the fund needs €12.3 bn today. Interest rate risk dominates (−1% → +15.9%), while longevity costs 4.8% of BEL at 99.5% in the own model versus 7.8% under the standard-formula shock. Older participants drive the longevity risk, younger ones the rate risk, and combined shocks exceed the sum of the separate effects.
B52: Sources: Human Mortality Database (Netherlands); EIOPA RFR 30-09-2026; synthetic portfolio. Inputs on Assumptions; Python results on Python_results.

Sheet Participants
A1: id | B1: sex | C1: age | D1: pension | E1: BEL_python
A2: 7142 | B2: Female | C2: 52 | D2: 23924.69 | E2: 184056.49
A3: 27818 | B3: Female | C3: 59 | D3: 22987.24 | E3: 225429.59
A4: 43572 | B4: Female | C4: 49 | D4: 11080.38 | E4: 77354.686
A5: 52877 | B5: Male | C5: 55 | D5: 3750.25 | E5: 30576.431
A6: 39845 | B6: Male | C6: 39 | D6: 6088.61 | E6: 30927.533
A7: 77945 | B7: Male | C7: 82 | D7: 21911.59 | E7: 146954.86
A8: 86536 | B8: Female | C8: 92 | D8: 21054.15 | E8: 81100.09
A9: 96726 | B9: Male | C9: 70 | D9: 15514.76 | E9: 189793.95
A10: 86333 | B10: Male | C10: 91 | D10: 36441.47 | E10: 134028.94
A11: 90629 | B11: Male | C11: 87 | D11: 27546.84 | E11: 132554.15

Sheet q_paths
A1: t | B1: 7142 | C1: 27818 | D1: 43572 | E1: 52877 | F1: 39845 | G1: 77945 | H1: 86536 | I1: 96726 | J1: 86333 | K1: 90629
A2: 0 | B2: 0.0023111772 | C2: 0.0045704948 | D2: 0.0016917956 | E2: 0.0037291341 | F2: 0.00076365579 | G2: 0.0663255 | H2: 0.18191612 | I2: 0.016236736 | J2: 0.19740984 | K2: 0.12458926
A3: 1 | B3: 0.0025582134 | C3: 0.0050088259 | D3: 0.0019027601 | E3: 0.0040053935 | F3: 0.00082374661 | G3: 0.073527059 | H3: 0.20262334 | I3: 0.017660689 | J3: 0.21795314 | K3: 0.14080581
A4: 2 | B4: 0.0028213401 | C4: 0.0054027673 | D4: 0.0021536252 | E4: 0.0043939762 | F4: 0.00090563408 | G4: 0.082140908 | H4: 0.22241706 | I4: 0.01881889 | J4: 0.24350357 | K4: 0.15629047
A5: 3 | B5: 0.0031262311 | C5: 0.0059380734 | D5: 0.0022316113 | E5: 0.0047451836 | F5: 0.00093583353 | G5: 0.093560565 | H5: 0.24547535 | I5: 0.020510454 | J5: 0.26083767 | K5: 0.17660051
A6: 4 | B6: 0.0033425562 | C6: 0.006339661 | D6: 0.0024875065 | E6: 0.0051977909 | F6: 0.00099481249 | G6: 0.10521006 | H6: 0.26780996 | I6: 0.022573938 | J6: 0.28897204 | K6: 0.19294152
A7: 5 | B7: 0.0035942385 | C7: 0.006686011 | D7: 0.0027477604 | E7: 0.0055646769 | F7: 0.0010601472 | G7: 0.1185136 | H7: 0.29726828 | I7: 0.02468976 | J7: 0.30621846 | K7: 0.21423042
A8: 6 | B8: 0.0039657948 | C8: 0.0073791223 | D8: 0.0030560905 | E8: 0.0058482846 | F8: 0.00115379 | G8: 0.13482359 | H8: 0.31163339 | I8: 0.027613165 | J8: 0.32452709 | K8: 0.24080585
A9: 7 | B9: 0.0043537148 | C9: 0.0078152636 | D9: 0.003259899 | E9: 0.0063617128 | F9: 0.0012649913 | G9: 0.15046158 | H9: 0.33846763 | I9: 0.030309728 | J9: 0.35209045 | K9: 0.25755161
A10: 8 | B10: 0.0047532883 | C10: 0.008498996 | D10: 0.0035063345 | E10: 0.0068247118 | F10: 0.0013702552 | G10: 0.17141003 | H10: 0.37085986 | I10: 0.033810362 | J10: 0.3644528 | K10: 0.28698664
A11: 9 | B11: 0.0051251798 | C11: 0.0090754939 | D11: 0.0038740686 | E11: 0.0073960709 | F11: 0.0015951808 | G11: 0.18748095 | H11: 0.41144863 | I11: 0.037870792 | J11: 0.37728896 | K11: 0.30403075
A12: 10 | B12: 0.0056809552 | C12: 0.0099492008 | D12: 0.0042639788 | E12: 0.0080076363 | F12: 0.0016336114 | G12: 0.20965388 | H12: 0.44755491 | I12: 0.043140949 | J12: 0.42962181 | K12: 0.32265932
A13: 11 | B13: 0.0060339163 | C13: 0.010604302 | D13: 0.0046477933 | E13: 0.0084580449 | F13: 0.0019009541 | G13: 0.23746882 | H13: 0.48567286 | I13: 0.047925902 | J13: 0.46056723 | K13: 0.34946892
... A82: 80 | B82: 1 | C82: 1 | D82: 1 | E82: 1 | F82: 1 | G82: 1 | H82: 1 | I82: 1 | J82: 1 | K82: 1

Sheet Discount
A1: t | B1: DF
A2: 0 | B2: 1
A3: 1 | B3: 0.96832605
A4: 2 | B4: 0.93461204
A5: 3 | B5: 0.90272746
A6: 4 | B6: 0.87204871
A7: 5 | B7: 0.84246144
A8: 6 | B8: 0.81364214
A9: 7 | B9: 0.78535335
A10: 8 | B10: 0.75753582
A11: 9 | B11: 0.73035807
A12: 10 | B12: 0.70366625
A13: 11 | B13: 0.67792403
... A82: 80 | B82: 0.069510949

Sheet CF_python
A1: t | B1: 7142 | C1: 27818 | D1: 43572 | E1: 52877 | F1: 39845 | G1: 77945 | H1: 86536 | I1: 96726 | J1: 86333 | K1: 90629
A2: 0 | B2: 0 | C2: 0 | D2: 0 | E2: 0 | F2: 0 | G2: 21911.59 | H2: 21054.15 | I2: 15514.76 | J2: 36441.47 | K2: 27546.84
A3: 1 | B3: 0 | C3: 0 | D3: 0 | E3: 0 | F3: 0 | G3: 20458.293 | H3: 17224.061 | I3: 15262.851 | J3: 29247.565 | K3: 24114.8
A4: 2 | B4: 0 | C4: 0 | D4: 0 | E4: 0 | F4: 0 | G4: 18954.055 | H4: 13734.064 | I4: 14993.298 | J4: 22872.967 | K4: 20719.296
A5: 3 | B5: 0 | C5: 0 | D5: 0 | E5: 0 | F5: 0 | G5: 17397.151 | H5: 10679.374 | I5: 14711.141 | J5: 17303.318 | K5: 17481.067
A6: 4 | B6: 0 | C6: 0 | D6: 0 | E6: 0 | F6: 0 | G6: 15769.464 | H6: 8057.8509 | I6: 14409.409 | J6: 12789.961 | K6: 14393.902
A7: 5 | B7: 0 | C7: 0 | D7: 0 | E7: 0 | F7: 0 | G7: 14110.358 | H7: 5899.8782 | I7: 14084.132 | J7: 9094.0196 | K7: 11616.721
A8: 6 | B8: 0 | C8: 0 | D8: 0 | E8: 0 | F8: 0 | G8: 12438.089 | H8: 4146.0315 | I8: 13736.398 | J8: 6309.2629 | K8: 9128.0656
A9: 7 | B9: 0 | C9: 0 | D9: 0 | E9: 0 | F9: 0 | G9: 10761.141 | H9: 2853.9897 | I9: 13357.093 | J9: 4261.7362 | K9: 6929.974
A10: 8 | B10: 0 | C10: 0 | D10: 0 | E10: 0 | F10: 0 | G10: 9142.0026 | H10: 1888.0066 | I10: 12952.243 | J10: 2761.2196 | K10: 5145.1481
A11: 9 | B11: 0 | C11: 21695.56 | D11: 0 | E11: 0 | F11: 0 | G11: 7574.9717 | H11: 1187.8207 | I11: 12514.323 | J11: 1754.8854 | K11: 3668.5593
A12: 10 | B12: 0 | C12: 21498.662 | D12: 0 | E12: 0 | F12: 0 | G12: 6154.8088 | H12: 699.09351 | I12: 12040.396 | J12: 1092.7865 | K12: 2553.2045
A13: 11 | B13: 0 | C13: 21284.768 | D13: 0 | E13: 0 | F13: 0 | G13: 4864.4292 | H13: 386.21077 | I13: 11520.961 | J13: 623.30158 | K13: 1729.3893
... A82: 80 | B82: 0 | C82: 0 | D82: 0 | E82: 0 | F82: 0 | G82: 0 | H82: 0 | I82: 0 | J82: 0 | K82: 0

Sheet Assumptions
A1: 68 | B1: 110 | C1: 2026 | D1: 0 | E1: 0
A2: RetirementAge | B2: MaxAge | C2: ValuationYear | D2: LongevityShock | E2: RateShift
A4: BEL for different LongevityShocks and RateShifts
A5: =Calc!L6 -> 146954.86 | B5: -0.01 | C5: 0 | D5: 0.01
A6: 0 | B6: 153254.75 | C6: 146954.86 | D6: 141154
A7: 0.1 | B7: 161982.33 | C7: 154931.19 | D7: 148463.61
A8: 0.2 | B8: 172063.7 | C8: 164093.68 | D8: 156815.87
A10: Percentual change from baseline
B11: -0.01 | C11: 0 | D11: 0.01
A12: 0 | B12: =B6/$C$6 -1 -> 0.042869552 | C12: =Calc!L6/C6-1 -> 0 | D12: =D6/$C$6 - 1 -> -0.039473756
A13: 0.1 | B13: =B7/$C$6 -1 -> 0.10225907 | C13: =C7/$C$6 -1 -> 0.054277395 | D13: =D7/$C$6 - 1 -> 0.010266768
A14: 0.2 | B14: =B8/$C$6 -1 -> 0.1708609 | C14: =C8/$C$6 -1 -> 0.11662644 | D14: =D8/$C$6 - 1 -> 0.067102274
G18: id: 77945 | M18: id: 7142
I19: Rate shift → | O19: Rate shift →
H20: -0.01 | I20: 0 | J20: 0.01 | N20: -0.01 | O20: 0 | P20: 0.01
G21: 0 | H21: 153254.75 | I21: 146954.86 | J21: 141154 | M21: 0 | N21: 236312.78 | O21: 184056.49 | P21: 144406.14
F22: Longevity shock ↓ | G22: 0.1 | H22: 161982.33 | I22: 154931.19 | J22: 148463.61 | L22: Longevity shock ↓ | M22: 0.1 | N22: 244588.64 | O22: 190013.4 | P22: 148737.8
G23: 0.2 | H23: 172063.7 | I23: 164093.68 | J23: 156815.87 | M23: 0.2 | N23: 253712.96 | O23: 196532.43 | P23: 153445.04
I25: Rate shift → | O25: Rate shift →
H26: -0.01 | I26: 0 | J26: 0.01 | N26: -0.01 | O26: 0 | P26: 0.01
G27: 0 | H27: 0.042869552 | I27: 0 | J27: -0.039473756 | M27: 0 | N27: 0.2839144 | O27: 0 | P27: -0.21542491
F28: Longevity shock ↓ | G28: 0.1 | H28: 0.10225907 | I28: 0.054277395 | J28: 0.010266768 | L28: Longevity shock ↓ | M28: 0.1 | N28: 0.32887808 | O28: 0.032364584 | P28: -0.19189048
G29: 0.2 | H29: 0.1708609 | I29: 0.11662644 | J29: 0.067102274 | M29: 0.2 | N29: 0.37845158 | O29: 0.067783202 | P29: -0.16631551
R31: Conclusion: The two participants are sensitive to different risks. The retiree (77945) is mainly exposed to longevity risk: a 20% decrease in mortality raises the BEL by 11.7%, while a 1% rate shift moves it by only about 4%. For the active participant (7142, age 52), the reverse holds: a 1% rate drop raises the BEL by 28.4%, against 6.8% for the longevity shock. This follows from duration: the active’s payments start 16 years from now, so discounting has much more impact, while the retiree’s high mortality rates make a relative decrease in mortality matter more. Combined shocks are larger than the sum of the separate effects, because the extra years of life are also discounted at a lower rate.

Sheet Calc
A1: Participant id | B1: =Reconciliation!B1 -> 77945
A2: Sex | B2: =_xlfn.XLOOKUP(B1, Participants!A:A, Participants!B:B) -> Male
A3: Age | B3: =_xlfn.XLOOKUP(B1,Participants!A:A,Participants!C:C) -> 82
A4: Pension | B4: =_xlfn.XLOOKUP(B1,Participants!A:A,Participants!D:D) -> 21911.59
A5: BEL Python | B5: =_xlfn.XLOOKUP(B1,Participants!A:A,Participants!E:E) -> 146954.86
A6: t | B6: Age | C6: q | D6: Survival | E6: Paying | F6: CF | G6: DF | H6: PV | I6: CF check | K6: BEL excel | L6: =SUM(H7:H87) -> 146954.86
A7: 0 | B7: =B3 -> 82 | C7: {=IF(B7>=MaxAge, 1, INDEX(q_paths!$B$2:$K$82, A7+1, MATCH($B$1, q_paths!$B$1:$K$1, 0)) * (1-LongevityShock))} -> 0.0663255 | D7: 1 | E7: =IF(B7>=RetirementAge, 1, 0) -> 1 | F7: =$B$4*D7*E7 -> 21911.59 | G7: {=IF(A7=0, 1, (INDEX(Discount!$B$2:$B$82, A7+1)^(-1/A7) + RateShift)^(-A7))} -> 1 | H7: =F7*G7 -> 21911.59 | I7: {=INDEX(CF_python!$B$2:$K$82, A7+1, MATCH($B$1, CF_python!$B$1:$K$1, 0)) - F7} -> 0 | K7: Duration | L7: =SUMPRODUCT(A7:A87,H7:H87) / SUM(H7:H87) -> 4.2558192
A8: =A7+1 -> 1 | B8: =B7+1 -> 83 | C8: {=IF(B8>=MaxAge, 1, INDEX(q_paths!$B$2:$K$82, A8+1, MATCH($B$1, q_paths!$B$1:$K$1, 0)) * (1-LongevityShock))} -> 0.073527059 | D8: =D7*(1-C7) -> 0.9336745 | E8: =IF(B8>=RetirementAge, 1, 0) -> 1 | F8: =$B$4*D8*E8 -> 20458.293 | G8: {=IF(A8=0, 1, (INDEX(Discount!$B$2:$B$82, A8+1)^(-1/A8) + RateShift)^(-A8))} -> 0.96832605 | H8: =F8*G8 -> 19810.298 | I8: {=INDEX(CF_python!$B$2:$K$82, A8+1, MATCH($B$1, CF_python!$B$1:$K$1, 0)) - F8} -> 0 | K8: Differnece vs python | L8: =L6-B5 -> 0
A9: =A8+1 -> 2 | B9: =B8+1 -> 84 | C9: {=IF(B9>=MaxAge, 1, INDEX(q_paths!$B$2:$K$82, A9+1, MATCH($B$1, q_paths!$B$1:$K$1, 0)) * (1-LongevityShock))} -> 0.082140908 | D9: =D8*(1-C8) -> 0.86502416 | E9: =IF(B9>=RetirementAge, 1, 0) -> 1 | F9: =$B$4*D9*E9 -> 18954.055 | G9: {=IF(A9=0, 1, (INDEX(Discount!$B$2:$B$82, A9+1)^(-1/A9) + RateShift)^(-A9))} -> 0.93461204 | H9: =F9*G9 -> 17714.688 | I9: {=INDEX(CF_python!$B$2:$K$82, A9+1, MATCH($B$1, CF_python!$B$1:$K$1, 0)) - F9} -> 0 | K9: Check | L9: =IF(ABS(L8)<1, "OK", "CHECK") -> OK
A10: =A9+1 -> 3 | B10: =B9+1 -> 85 | C10: {=IF(B10>=MaxAge, 1, INDEX(q_paths!$B$2:$K$82, A10+1, MATCH($B$1, q_paths!$B$1:$K$1, 0)) * (1-LongevityShock))} -> 0.093560565 | D10: =D9*(1-C9) -> 0.79397029 | E10: =IF(B10>=RetirementAge, 1, 0) -> 1 | F10: =$B$4*D10*E10 -> 17397.151 | G10: {=IF(A10=0, 1, (INDEX(Discount!$B$2:$B$82, A10+1)^(-1/A10) + RateShift)^(-A10))} -> 0.90272746 | H10: =F10*G10 -> 15704.886 | I10: {=INDEX(CF_python!$B$2:$K$82, A10+1, MATCH($B$1, CF_python!$B$1:$K$1, 0)) - F10} -> 0 | K10: Max CF diff | L10: {=MAX(ABS(I7:I87))} -> 0
A11: =A10+1 -> 4 | B11: =B10+1 -> 86 | C11: {=IF(B11>=MaxAge, 1, INDEX(q_paths!$B$2:$K$82, A11+1, MATCH($B$1, q_paths!$B$1:$K$1, 0)) * (1-LongevityShock))} -> 0.10521006 | D11: =D10*(1-C10) -> 0.71968598 | E11: =IF(B11>=RetirementAge, 1, 0) -> 1 | F11: =$B$4*D11*E11 -> 15769.464 | G11: {=IF(A11=0, 1, (INDEX(Discount!$B$2:$B$82, A11+1)^(-1/A11) + RateShift)^(-A11))} -> 0.87204871 | H11: =F11*G11 -> 13751.741 | I11: {=INDEX(CF_python!$B$2:$K$82, A11+1, MATCH($B$1, CF_python!$B$1:$K$1, 0)) - F11} -> 0
A12: =A11+1 -> 5 | B12: =B11+1 -> 87 | C12: {=IF(B12>=MaxAge, 1, INDEX(q_paths!$B$2:$K$82, A12+1, MATCH($B$1, q_paths!$B$1:$K$1, 0)) * (1-LongevityShock))} -> 0.1185136 | D12: =D11*(1-C11) -> 0.64396778 | E12: =IF(B12>=RetirementAge, 1, 0) -> 1 | F12: =$B$4*D12*E12 -> 14110.358 | G12: {=IF(A12=0, 1, (INDEX(Discount!$B$2:$B$82, A12+1)^(-1/A12) + RateShift)^(-A12))} -> 0.84246144 | H12: =F12*G12 -> 11887.432 | I12: {=INDEX(CF_python!$B$2:$K$82, A12+1, MATCH($B$1, CF_python!$B$1:$K$1, 0)) - F12} -> 0
A13: =A12+1 -> 6 | B13: =B12+1 -> 88 | C13: {=IF(B13>=MaxAge, 1, INDEX(q_paths!$B$2:$K$82, A13+1, MATCH($B$1, q_paths!$B$1:$K$1, 0)) * (1-LongevityShock))} -> 0.13482359 | D13: =D12*(1-C12) -> 0.56764884 | E13: =IF(B13>=RetirementAge, 1, 0) -> 1 | F13: =$B$4*D13*E13 -> 12438.089 | G13: {=IF(A13=0, 1, (INDEX(Discount!$B$2:$B$82, A13+1)^(-1/A13) + RateShift)^(-A13))} -> 0.81364214 | H13: =F13*G13 -> 10120.153 | I13: {=INDEX(CF_python!$B$2:$K$82, A13+1, MATCH($B$1, CF_python!$B$1:$K$1, 0)) - F13} -> 0
A14: =A13+1 -> 7 | B14: =B13+1 -> 89 | C14: {=IF(B14>=MaxAge, 1, INDEX(q_paths!$B$2:$K$82, A14+1, MATCH($B$1, q_paths!$B$1:$K$1, 0)) * (1-LongevityShock))} -> 0.15046158 | D14: =D13*(1-C13) -> 0.49111638 | E14: =IF(B14>=RetirementAge, 1, 0) -> 1 | F14: =$B$4*D14*E14 -> 10761.141 | G14: {=IF(A14=0, 1, (INDEX(Discount!$B$2:$B$82, A14+1)^(-1/A14) + RateShift)^(-A14))} -> 0.78535335 | H14: =F14*G14 -> 8451.298 | I14: {=INDEX(CF_python!$B$2:$K$82, A14+1, MATCH($B$1, CF_python!$B$1:$K$1, 0)) - F14} -> 0
A15: =A14+1 -> 8 | B15: =B14+1 -> 90 | C15: {=IF(B15>=MaxAge, 1, INDEX(q_paths!$B$2:$K$82, A15+1, MATCH($B$1, q_paths!$B$1:$K$1, 0)) * (1-LongevityShock))} -> 0.17141003 | D15: =D14*(1-C14) -> 0.41722224 | E15: =IF(B15>=RetirementAge, 1, 0) -> 1 | F15: =$B$4*D15*E15 -> 9142.0026 | G15: {=IF(A15=0, 1, (INDEX(Discount!$B$2:$B$82, A15+1)^(-1/A15) + RateShift)^(-A15))} -> 0.75753582 | H15: =F15*G15 -> 6925.3944 | I15: {=INDEX(CF_python!$B$2:$K$82, A15+1, MATCH($B$1, CF_python!$B$1:$K$1, 0)) - F15} -> 0
A16: =A15+1 -> 9 | B16: =B15+1 -> 91 | C16: {=IF(B16>=MaxAge, 1, INDEX(q_paths!$B$2:$K$82, A16+1, MATCH($B$1, q_paths!$B$1:$K$1, 0)) * (1-LongevityShock))} -> 0.18748095 | D16: =D15*(1-C15) -> 0.34570616 | E16: =IF(B16>=RetirementAge, 1, 0) -> 1 | F16: =$B$4*D16*E16 -> 7574.9717 | G16: {=IF(A16=0, 1, (INDEX(Discount!$B$2:$B$82, A16+1)^(-1/A16) + RateShift)^(-A16))} -> 0.73035807 | H16: =F16*G16 -> 5532.4417 | I16: {=INDEX(CF_python!$B$2:$K$82, A16+1, MATCH($B$1, CF_python!$B$1:$K$1, 0)) - F16} -> 0
A17: =A16+1 -> 10 | B17: =B16+1 -> 92 | C17: {=IF(B17>=MaxAge, 1, INDEX(q_paths!$B$2:$K$82, A17+1, MATCH($B$1, q_paths!$B$1:$K$1, 0)) * (1-LongevityShock))} -> 0.20965388 | D17: =D16*(1-C16) -> 0.28089284 | E17: =IF(B17>=RetirementAge, 1, 0) -> 1 | F17: =$B$4*D17*E17 -> 6154.8088 | G17: {=IF(A17=0, 1, (INDEX(Discount!$B$2:$B$82, A17+1)^(-1/A17) + RateShift)^(-A17))} -> 0.70366625 | H17: =F17*G17 -> 4330.9312 | I17: {=INDEX(CF_python!$B$2:$K$82, A17+1, MATCH($B$1, CF_python!$B$1:$K$1, 0)) - F17} -> 0
A18: =A17+1 -> 11 | B18: =B17+1 -> 93 | C18: {=IF(B18>=MaxAge, 1, INDEX(q_paths!$B$2:$K$82, A18+1, MATCH($B$1, q_paths!$B$1:$K$1, 0)) * (1-LongevityShock))} -> 0.23746882 | D18: =D17*(1-C17) -> 0.22200257 | E18: =IF(B18>=RetirementAge, 1, 0) -> 1 | F18: =$B$4*D18*E18 -> 4864.4292 | G18: {=IF(A18=0, 1, (INDEX(Discount!$B$2:$B$82, A18+1)^(-1/A18) + RateShift)^(-A18))} -> 0.67792403 | H18: =F18*G18 -> 3297.7135 | I18: {=INDEX(CF_python!$B$2:$K$82, A18+1, MATCH($B$1, CF_python!$B$1:$K$1, 0)) - F18} -> 0
A19: =A18+1 -> 12 | B19: =B18+1 -> 94 | C19: {=IF(B19>=MaxAge, 1, INDEX(q_paths!$B$2:$K$82, A19+1, MATCH($B$1, q_paths!$B$1:$K$1, 0)) * (1-LongevityShock))} -> 0.25349174 | D19: =D18*(1-C18) -> 0.16928388 | E19: =IF(B19>=RetirementAge, 1, 0) -> 1 | F19: =$B$4*D19*E19 -> 3709.279 | G19: {=IF(A19=0, 1, (INDEX(Discount!$B$2:$B$82, A19+1)^(-1/A19) + RateShift)^(-A19))} -> 0.6529473 | H19: =F19*G19 -> 2421.9637 | I19: {=INDEX(CF_python!$B$2:$K$82, A19+1, MATCH($B$1, CF_python!$B$1:$K$1, 0)) - F19} -> 0
A20: =A19+1 -> 13 | B20: =B19+1 -> 95 | C20: {=IF(B20>=MaxAge, 1, INDEX(q_paths!$B$2:$K$82, A20+1, MATCH($B$1, q_paths!$B$1:$K$1, 0)) * (1-LongevityShock))} -> 0.28452001 | D20: =D19*(1-C19) -> 0.12637181 | E20: =IF(B20>=RetirementAge, 1, 0) -> 1 | F20: =$B$4*D20*E20 -> 2769.0074 | G20: {=IF(A20=0, 1, (INDEX(Discount!$B$2:$B$82, A20+1)^(-1/A20) + RateShift)^(-A20))} -> 0.62905486 | H20: =F20*G20 -> 1741.8576 | I20: {=INDEX(CF_python!$B$2:$K$82, A20+1, MATCH($B$1, CF_python!$B$1:$K$1, 0)) - F20} -> 0
A21: =A20+1 -> 14 | B21: =B20+1 -> 96 | C21: {=IF(B21>=MaxAge, 1, INDEX(q_paths!$B$2:$K$82, A21+1, MATCH($B$1, q_paths!$B$1:$K$1, 0)) * (1-LongevityShock))} -> 0.30131303 | D21: =D20*(1-C20) -> 0.090416505 | E21: =IF(B21>=RetirementAge, 1, 0) -> 1 | F21: =$B$4*D21*E21 -> 1981.1694 | G21: {=IF(A21=0, 1, (INDEX(Discount!$B$2:$B$82, A21+1)^(-1/A21) + RateShift)^(-A21))} -> 0.60628246 | H21: =F21*G21 -> 1201.1483 | I21: {=INDEX(CF_python!$B$2:$K$82, A21+1, MATCH($B$1, CF_python!$B$1:$K$1, 0)) - F21} -> 0
A22: =A21+1 -> 15 | B22: =B21+1 -> 97 | C22: {=IF(B22>=MaxAge, 1, INDEX(q_paths!$B$2:$K$82, A22+1, MATCH($B$1, q_paths!$B$1:$K$1, 0)) * (1-LongevityShock))} -> 0.3203359 | D22: =D21*(1-C21) -> 0.063172834 | E22: =IF(B22>=RetirementAge, 1, 0) -> 1 | F22: =$B$4*D22*E22 -> 1384.2172 | G22: {=IF(A22=0, 1, (INDEX(Discount!$B$2:$B$82, A22+1)^(-1/A22) + RateShift)^(-A22))} -> 0.58465594 | H22: =F22*G22 -> 809.29084 | I22: {=INDEX(CF_python!$B$2:$K$82, A22+1, MATCH($B$1, CF_python!$B$1:$K$1, 0)) - F22} -> 0
... A87: =A86+1 -> 80 | B87: =B86+1 -> 162 | C87: {=IF(B87>=MaxAge, 1, INDEX(q_paths!$B$2:$K$82, A87+1, MATCH($B$1, q_paths!$B$1:$K$1, 0)) * (1-LongevityShock))} -> 1 | D87: =D86*(1-C86) -> 0 | E87: =IF(B87>=RetirementAge, 1, 0) -> 1 | F87: =$B$4*D87*E87 -> 0 | G87: {=IF(A87=0, 1, (INDEX(Discount!$B$2:$B$82, A87+1)^(-1/A87) + RateShift)^(-A87))} -> 0.069510949 | H87: =F87*G87 -> 0 | I87: {=INDEX(CF_python!$B$2:$K$82, A87+1, MATCH($B$1, CF_python!$B$1:$K$1, 0)) - F87} -> 0

Sheet Reconciliation
A1: Selected id | B1: 77945 | D1: Row 5 (hidden template row)
A4: id | B4: BEL Excel | C4: Duration | D4: BEL Python | E4: Difference | F4: Check
B5: =Calc!L6 -> 146954.86 | C5: =Calc!L7 -> 4.2558192
A6: =Participants!A2 -> 7142 | B6: 184056.49 | C6: 25.491075 | D6: =_xlfn.XLOOKUP(A6, Participants!A:A, Participants!E:E) -> 184056.49 | E6: =B6-D6 -> 0 | F6: =IF(ABS(E6)<1, "OK", "CHECK") -> OK
A7: =Participants!A3 -> 27818 | B7: 225429.59 | C7: 18.315259 | D7: =_xlfn.XLOOKUP(A7, Participants!A:A, Participants!E:E) -> 225429.59 | E7: =B7-D7 -> 0 | F7: =IF(ABS(E7)<1, "OK", "CHECK") -> OK
A8: =Participants!A4 -> 43572 | B8: 77354.686 | C8: 28.545219 | D8: =_xlfn.XLOOKUP(A8, Participants!A:A, Participants!E:E) -> 77354.686 | E8: =B8-D8 -> 0 | F8: =IF(ABS(E8)<1, "OK", "CHECK") -> OK
A9: =Participants!A5 -> 52877 | B9: 30576.431 | C9: 22.070475 | D9: =_xlfn.XLOOKUP(A9, Participants!A:A, Participants!E:E) -> 30576.431 | E9: =B9-D9 -> 0 | F9: =IF(ABS(E9)<1, "OK", "CHECK") -> OK
A10: =Participants!A6 -> 39845 | B10: 30927.533 | C10: 38.496496 | D10: =_xlfn.XLOOKUP(A10, Participants!A:A, Participants!E:E) -> 30927.533 | E10: =B10-D10 -> 0 | F10: =IF(ABS(E10)<1, "OK", "CHECK") -> OK
A11: =Participants!A7 -> 77945 | B11: 146954.86 | C11: 4.2558192 | D11: =_xlfn.XLOOKUP(A11, Participants!A:A, Participants!E:E) -> 146954.86 | E11: =B11-D11 -> 0 | F11: =IF(ABS(E11)<1, "OK", "CHECK") -> OK
A12: =Participants!A8 -> 86536 | B12: 81100.09 | C12: 2.3439361 | D12: =_xlfn.XLOOKUP(A12, Participants!A:A, Participants!E:E) -> 81100.09 | E12: =B12-D12 -> 0 | F12: =IF(ABS(E12)<1, "OK", "CHECK") -> OK
A13: =Participants!A9 -> 96726 | B13: 189793.95 | C13: 7.9155157 | D13: =_xlfn.XLOOKUP(A13, Participants!A:A, Participants!E:E) -> 189793.95 | E13: =B13-D13 -> 0 | F13: =IF(ABS(E13)<1, "OK", "CHECK") -> OK
A14: =Participants!A10 -> 86333 | B14: 134028.94 | C14: 2.2451659 | D14: =_xlfn.XLOOKUP(A14, Participants!A:A, Participants!E:E) -> 134028.94 | E14: =B14-D14 -> 0 | F14: =IF(ABS(E14)<1, "OK", "CHECK") -> OK
A15: =Participants!A11 -> 90629 | B15: 132554.15 | C15: 3.0222939 | D15: =_xlfn.XLOOKUP(A15, Participants!A:A, Participants!E:E) -> 132554.15 | E15: =B15-D15 -> 0 | F15: =IF(ABS(E15)<1, "OK", "CHECK") -> OK
B17: =SUM(B6:B15) -> 1232776.7 | D17: =SUM(D6:D15) -> 1232776.7 | E17: =B17-D17 -> 0 | F17: =IF(COUNTIF(F6:F15,"OK")=10, "All reconciled", "Check") -> All reconciled

Sheet Python_results
A1: Fund-level results from the Python model
A2: Source: python/liability_model.py, output data/shock_results.csv and summarise_bel() output (100,000 participants, valuation 30-09-2026). Blue cells are hardcoded inputs copied from Python.
A4: Scenario | B4: BEL (€ bn) | C4: Duration (yrs) | D4: Change (€ mln) | E4: Change (%)
A5: Base | B5: 12.278379 | C5: 14.489911 | D5: =(B5-$B$5)*1000 -> 0 | E5: =B5/$B$5-1 -> 0
A6: Longevity -20% q | B6: 13.237019 | C6: 14.911614 | D6: =(B6-$B$5)*1000 -> 958.63997 | E6: =B6/$B$5-1 -> 0.078075451
A7: Rates -1% | B7: 14.231167 | C7: 15.950989 | D7: =(B7-$B$5)*1000 -> 1952.7884 | E7: =B7/$B$5-1 -> 0.15904285
A8: Rates +1% | B8: 10.750233 | C8: 13.190896 | D8: =(B8-$B$5)*1000 -> -1528.1457 | E8: =B8/$B$5-1 -> -0.12445826
A11: Stochastic BEL (1,000 Lee-Carter mortality scenarios)
A12: Central BEL (€ bn) | B12: =B5 -> 12.278379
A13: Mean of scenarios (€ bn) | B13: 12.27
A14: Std of scenarios (€ bn) | B14: 0.27
A15: 5% quantile (€ bn) | B15: 11.82
A16: 50% quantile (€ bn) | B16: 12.28
A17: 95% quantile (€ bn) | B17: 12.69
A18: 99.5% minus central (€ mln) | B18: 583
A19: 99.5% quantile (€ bn) | B19: =B12+B18/1000 -> 12.861379
A20: Longevity capital, own model (% of BEL) | B20: =B18/1000/B12 -> 0.047481838
A21: Longevity capital, standard formula -20% q (% of BEL) | B21: =E6 -> 0.078075451
